ERROR 2025-08-26 20:17:25,596 log 15532 8328 Internal Server Error: /
Traceback (most recent call last):
  File "C:\Users\a\AppData\Local\Programs\Python\Python313\Lib\site-packages\django\core\handlers\exception.py", line 55, in inner
    response = get_response(request)
  File "C:\Users\a\AppData\Local\Programs\Python\Python313\Lib\site-packages\django\core\handlers\base.py", line 220, in _get_response
    response = response.render()
  File "C:\Users\a\AppData\Local\Programs\Python\Python313\Lib\site-packages\django\template\response.py", line 114, in render
    self.content = self.rendered_content
                   ^^^^^^^^^^^^^^^^^^^^^
  File "C:\Users\a\AppData\Local\Programs\Python\Python313\Lib\site-packages\django\template\response.py", line 90, in rendered_content
    template = self.resolve_template(self.template_name)
  File "C:\Users\a\AppData\Local\Programs\Python\Python313\Lib\site-packages\django\template\response.py", line 72, in resolve_template
    return select_template(template, using=self.using)
  File "C:\Users\a\AppData\Local\Programs\Python\Python313\Lib\site-packages\django\template\loader.py", line 47, in select_template
    raise TemplateDoesNotExist(", ".join(template_name_list), chain=chain)
django.template.exceptions.TemplateDoesNotExist: index.html
ERROR 2025-08-26 20:17:25,601 basehttp 15532 8328 "GET / HTTP/1.1" 500 80011
ERROR 2025-08-26 20:17:25,743 log 15532 8328 Internal Server Error: /favicon.ico
Traceback (most recent call last):
  File "C:\Users\a\AppData\Local\Programs\Python\Python313\Lib\site-packages\django\core\handlers\exception.py", line 55, in inner
    response = get_response(request)
  File "C:\Users\a\AppData\Local\Programs\Python\Python313\Lib\site-packages\django\core\handlers\base.py", line 220, in _get_response
    response = response.render()
  File "C:\Users\a\AppData\Local\Programs\Python\Python313\Lib\site-packages\django\template\response.py", line 114, in render
    self.content = self.rendered_content
                   ^^^^^^^^^^^^^^^^^^^^^
  File "C:\Users\a\AppData\Local\Programs\Python\Python313\Lib\site-packages\django\template\response.py", line 90, in rendered_content
    template = self.resolve_template(self.template_name)
  File "C:\Users\a\AppData\Local\Programs\Python\Python313\Lib\site-packages\django\template\response.py", line 72, in resolve_template
    return select_template(template, using=self.using)
  File "C:\Users\a\AppData\Local\Programs\Python\Python313\Lib\site-packages\django\template\loader.py", line 47, in select_template
    raise TemplateDoesNotExist(", ".join(template_name_list), chain=chain)
django.template.exceptions.TemplateDoesNotExist: index.html
ERROR 2025-08-26 20:17:25,745 basehttp 15532 8328 "GET /favicon.ico HTTP/1.1" 500 79914
ERROR 2025-08-26 20:51:17,601 log 4348 11100 Internal Server Error: /
Traceback (most recent call last):
  File "C:\Users\a\AppData\Local\Programs\Python\Python313\Lib\site-packages\django\core\handlers\exception.py", line 55, in inner
    response = get_response(request)
  File "C:\Users\a\AppData\Local\Programs\Python\Python313\Lib\site-packages\django\core\handlers\base.py", line 220, in _get_response
    response = response.render()
  File "C:\Users\a\AppData\Local\Programs\Python\Python313\Lib\site-packages\django\template\response.py", line 114, in render
    self.content = self.rendered_content
                   ^^^^^^^^^^^^^^^^^^^^^
  File "C:\Users\a\AppData\Local\Programs\Python\Python313\Lib\site-packages\django\template\response.py", line 90, in rendered_content
    template = self.resolve_template(self.template_name)
  File "C:\Users\a\AppData\Local\Programs\Python\Python313\Lib\site-packages\django\template\response.py", line 72, in resolve_template
    return select_template(template, using=self.using)
  File "C:\Users\a\AppData\Local\Programs\Python\Python313\Lib\site-packages\django\template\loader.py", line 47, in select_template
    raise TemplateDoesNotExist(", ".join(template_name_list), chain=chain)
django.template.exceptions.TemplateDoesNotExist: index.html
ERROR 2025-08-26 20:51:17,604 basehttp 4348 11100 "GET / HTTP/1.1" 500 80011
ERROR 2025-08-26 20:51:17,749 log 4348 11100 Internal Server Error: /favicon.ico
Traceback (most recent call last):
  File "C:\Users\a\AppData\Local\Programs\Python\Python313\Lib\site-packages\django\core\handlers\exception.py", line 55, in inner
    response = get_response(request)
  File "C:\Users\a\AppData\Local\Programs\Python\Python313\Lib\site-packages\django\core\handlers\base.py", line 220, in _get_response
    response = response.render()
  File "C:\Users\a\AppData\Local\Programs\Python\Python313\Lib\site-packages\django\template\response.py", line 114, in render
    self.content = self.rendered_content
                   ^^^^^^^^^^^^^^^^^^^^^
  File "C:\Users\a\AppData\Local\Programs\Python\Python313\Lib\site-packages\django\template\response.py", line 90, in rendered_content
    template = self.resolve_template(self.template_name)
  File "C:\Users\a\AppData\Local\Programs\Python\Python313\Lib\site-packages\django\template\response.py", line 72, in resolve_template
    return select_template(template, using=self.using)
  File "C:\Users\a\AppData\Local\Programs\Python\Python313\Lib\site-packages\django\template\loader.py", line 47, in select_template
    raise TemplateDoesNotExist(", ".join(template_name_list), chain=chain)
django.template.exceptions.TemplateDoesNotExist: index.html
ERROR 2025-08-26 20:51:17,751 basehttp 4348 11100 "GET /favicon.ico HTTP/1.1" 500 79914
